<robot name="simple_two_axis_robot">

  <link name="base_box">

    <visual>
    
      <origin xyz="0 0 0.6" rpy="0 0 0"/>
      <geometry>
        
        <box size="0.5 0.5 1.2"/>
      </geometry>
      
      <material name="white">
        <color rgba="1 1 1 1"/>
      </material>
    </visual>

    
    <collision>
      
      <origin xyz="0 0 0.6" rpy="0 0 0"/>
      <geometry>
        
        <box size="0.5 0.5 1.2"/>
      </geometry>
  
    </collision>

    
    <inertial>
        
        <origin xyz="0 0 0" rpy="0 0 0" />
        
        <mass value="1" />
      
        <inertia ixx="0.000034533333" 
            ixy="0"  ixz="0"
            iyx="0"  iyy="0.000034533333" 
            iyz="0"
            izx="0"  izy="0"  izz="0.0000648" />
    </inertial>
  </link>


  <!-- link1 -->
  <link name="link1">
    
    <visual>
      <origin xyz="0 0 0.25" rpy="0 0 0"/>
      <geometry>
        <box size="0.05 0.05 0.5"/>
      </geometry>
      <material name="red">
        <color rgba="1 0 0 1"/>
      </material>
    </visual>
      
  
    <collision>
      <origin xyz="0 0 0.25" rpy="0 0 0"/>
      <geometry>
        <box size="0.05 0.05 0.5"/>
      </geometry>
    </collision>

    
    <inertial>
        <origin xyz="0 0 0" rpy="0 0 0" />
        <mass value="0.1" />
        <inertia ixx="0.000034533333" 
            ixy="0"  ixz="0"
            iyx="0"  iyy="0.000034533333" 
            iyz="0"
            izx="0"  izy="0"  izz="0.0000648" />
    </inertial>
  </link>


  <joint name="joint1" type="continuous"> 
    
    <parent link="base_box"/>
    
    <child link="link1"/>
    
    <origin xyz="0 0.4 1.2" rpy="0 -1.57 0"/>
    <axis xyz="0 1 0"/>
  </joint>
  
  <link name="link2">
    
    <visual>
      <origin xyz="0 0.0 0.25" rpy="0 0 0"/>
      <geometry>
        <box size="0.05 0.05 0.5"/>
      </geometry>
      <material name="green">
        <color rgba="0 1 0 1"/>
      </material>
    </visual>

  
    <collision>
      <origin xyz="0 0.0 0.25" rpy="0 0 0"/>
      <geometry>
        <box size="0.05 0.05 0.5"/>
      </geometry>
    </collision>

  
    <inertial>
        <origin xyz="0 0 0" rpy="0 0 0" />
        <mass value="0.1" />
        <inertia ixx="0.000034533333" 
            ixy="0"  ixz="0"
            iyx="0"  iyy="0.000034533333" 
            iyz="0"
            izx="0"  izy="0"  izz="0.0000648" />
    </inertial>
  </link>


  <joint name="joint2" type="continuous">
    <parent link="link1"/>
    <child link="link2"/>
    <origin xyz="0 0 0.5" rpy="0 0 0"/>
    <axis xyz="0 1 0"/>
  </joint>
  

  <link name="camera_link">
    
    <visual>
      <origin xyz="0.0 0.0 0.0" rpy="0 0 0"/>
      <geometry>
        <box size="0.01 0.01 0.01"/>
      </geometry>
      <material name="black">
        <color rgba="0 0 0 1"/>
      </material>
    </visual>

  
    <collision>
      <origin xyz="0.0 0.0 0.0" rpy="0 0 0"/>
      <geometry>
        <box size="0.01 0.01 0.01"/>
      </geometry>
    </collision>

    
    <inertial>
        <origin xyz="0 0 0" rpy="0 0 0" />
        <mass value="0.0001" />
        <inertia ixx="0.000034533333" 
            ixy="0"  ixz="0"
            iyx="0"  iyy="0.000034533333" 
            iyz="0"
            izx="0"  izy="0"  izz="0.0000648" />
    </inertial>
  </link>

  <joint name="camera_joint" type="fixed">
    <parent link="link2"/>
    <child link="camera_link"/>
    <origin xyz="0.03 0.0 0.495" rpy="0 0 0"/>
    <axis xyz="0 0 1"/>
  </joint>


  <link name="target_position_vertual_link"/>

  <joint name="camera_target_joint" type="fixed">
    <parent link="camera_link"/>
    <child link="target_position_vertual_link"/>
    <origin xyz="0.0 0.0 0.01" rpy="0 0 0"/>
    <axis xyz="0 0 1"/>
  </joint>

  <!--force sensor link###############################################################-->
  <!-- force sensor link -->
  <link name="force_sensor_link">
  
    <visual>
      <origin xyz="0 0.0 0.025" rpy="0 0 0"/>
      <geometry>
        <box size="0.05 0.05 0.05"/>
      </geometry>
      <material name="red">
        <color rgba="1 0 0 1"/>
      </material>
    </visual>

  
    <collision>
      <origin xyz="0 0.0 0.025" rpy="0 0 0"/>
      <geometry>
        <box size="0.05 0.05 0.05"/>
      </geometry>
    </collision>

    
    <inertial>
        <origin xyz="0 0 0" rpy="0 0 0" />
        <mass value="0.0001" />
        <inertia ixx="0.000034533333" 
            ixy="0"  ixz="0"
            iyx="0"  iyy="0.000034533333" 
            iyz="0"
            izx="0"  izy="0"  izz="0.0000648" />
    </inertial>
  </link>

  <joint name="force_sensor_joint" type="fixed">
    <parent link="link2"/>
    <child link="force_sensor_link"/>
    <origin xyz="0.0 0.0 0.5" rpy="0 0 0"/>
    <axis xyz="0 0 1"/>
  </joint>

</robot>